

Thu Dec  9 05:32:03 2021
<<ERROR polling>>
Traceback (most recent call last):
  File "/SoftDev/telefacebot-python3/lib/python3.7/site-packages/urllib3/connectionpool.py", line 445, in _make_request
    six.raise_from(e, None)
  File "<string>", line 3, in raise_from
  File "/SoftDev/telefacebot-python3/lib/python3.7/site-packages/urllib3/connectionpool.py", line 440, in _make_request
    httplib_response = conn.getresponse()
  File "/usr/lib64/python3.7/http/client.py", line 1321, in getresponse
    response.begin()
  File "/usr/lib64/python3.7/http/client.py", line 296, in begin
    version, status, reason = self._read_status()
  File "/usr/lib64/python3.7/http/client.py", line 257, in _read_status
    line = str(self.fp.readline(_MAXLINE + 1), "iso-8859-1")
  File "/usr/lib64/python3.7/socket.py", line 589, in readinto
    return self._sock.recv_into(b)
  File "/usr/lib64/python3.7/ssl.py", line 1052, in recv_into
    return self.read(nbytes, buffer)
  File "/usr/lib64/python3.7/ssl.py", line 911, in read
    return self._sslobj.read(len, buffer)
TimeoutError: [Errno 110] Connection timed out

During handling of the above exception, another exception occurred:

Traceback (most recent call last):
  File "/SoftDev/telefacebot-python3/lib/python3.7/site-packages/requests/adapters.py", line 449, in send
    timeout=timeout
  File "/SoftDev/telefacebot-python3/lib/python3.7/site-packages/urllib3/connectionpool.py", line 756, in urlopen
    method, url, error=e, _pool=self, _stacktrace=sys.exc_info()[2]
  File "/SoftDev/telefacebot-python3/lib/python3.7/site-packages/urllib3/util/retry.py", line 532, in increment
    raise six.reraise(type(error), error, _stacktrace)
  File "/SoftDev/telefacebot-python3/lib/python3.7/site-packages/urllib3/packages/six.py", line 770, in reraise
    raise value
  File "/SoftDev/telefacebot-python3/lib/python3.7/site-packages/urllib3/connectionpool.py", line 706, in urlopen
    chunked=chunked,
  File "/SoftDev/telefacebot-python3/lib/python3.7/site-packages/urllib3/connectionpool.py", line 447, in _make_request
    self._raise_timeout(err=e, url=url, timeout_value=read_timeout)
  File "/SoftDev/telefacebot-python3/lib/python3.7/site-packages/urllib3/connectionpool.py", line 354, in _raise_timeout
    self, url, "Read timed out. (read timeout=%s)" % timeout_value
urllib3.exceptions.ReadTimeoutError: HTTPSConnectionPool(host='api.telegram.org', port=443): Read timed out. (read timeout=6010)

During handling of the above exception, another exception occurred:

Traceback (most recent call last):
  File "./webbasicchatbot.py", line 66, in telegram_polling
    mybot.polling(none_stop=True, timeout=6000)
  File "/SoftDev/telefacebot-python3/lib/python3.7/site-packages/telebot/__init__.py", line 392, in polling
    self.__threaded_polling(none_stop, interval, timeout)
  File "/SoftDev/telefacebot-python3/lib/python3.7/site-packages/telebot/__init__.py", line 415, in __threaded_polling
    polling_thread.raise_exceptions()
  File "/SoftDev/telefacebot-python3/lib/python3.7/site-packages/telebot/util.py", line 79, in raise_exceptions
    six.reraise(self.exc_info[0], self.exc_info[1], self.exc_info[2])
  File "/SoftDev/telefacebot-python3/lib/python3.7/site-packages/six.py", line 719, in reraise
    raise value
  File "/SoftDev/telefacebot-python3/lib/python3.7/site-packages/telebot/util.py", line 60, in run
    task(*args, **kwargs)
  File "/SoftDev/telefacebot-python3/lib/python3.7/site-packages/telebot/__init__.py", line 279, in __retrieve_updates
    updates = self.get_updates(offset=(self.last_update_id + 1), timeout=timeout)
  File "/SoftDev/telefacebot-python3/lib/python3.7/site-packages/telebot/__init__.py", line 249, in get_updates
    json_updates = apihelper.get_updates(self.token, offset, limit, timeout, allowed_updates)
  File "/SoftDev/telefacebot-python3/lib/python3.7/site-packages/telebot/apihelper.py", line 194, in get_updates
    return _make_request(token, method_url, params=payload)
  File "/SoftDev/telefacebot-python3/lib/python3.7/site-packages/telebot/apihelper.py", line 58, in _make_request
    timeout=(connect_timeout, read_timeout), proxies=proxy)
  File "/SoftDev/telefacebot-python3/lib/python3.7/site-packages/requests/sessions.py", line 542, in request
    resp = self.send(prep, **send_kwargs)
  File "/SoftDev/telefacebot-python3/lib/python3.7/site-packages/requests/sessions.py", line 655, in send
    r = adapter.send(request, **kwargs)
  File "/SoftDev/telefacebot-python3/lib/python3.7/site-packages/requests/adapters.py", line 529, in send
    raise ReadTimeout(e, request=request)
requests.exceptions.ReadTimeout: HTTPSConnectionPool(host='api.telegram.org', port=443): Read timed out. (read timeout=6010)

<<ERROR polling>>

Thu Dec  9 07:12:24 2021
<<ERROR polling>>
Traceback (most recent call last):
  File "/SoftDev/telefacebot-python3/lib/python3.7/site-packages/urllib3/connection.py", line 175, in _new_conn
    (self._dns_host, self.port), self.timeout, **extra_kw
  File "/SoftDev/telefacebot-python3/lib/python3.7/site-packages/urllib3/util/connection.py", line 73, in create_connection
    for res in socket.getaddrinfo(host, port, family, socket.SOCK_STREAM):
  File "/usr/lib64/python3.7/socket.py", line 748, in getaddrinfo
    for res in _socket.getaddrinfo(host, port, family, type, proto, flags):
socket.gaierror: [Errno -3] Temporary failure in name resolution

During handling of the above exception, another exception occurred:

Traceback (most recent call last):
  File "/SoftDev/telefacebot-python3/lib/python3.7/site-packages/urllib3/connectionpool.py", line 706, in urlopen
    chunked=chunked,
  File "/SoftDev/telefacebot-python3/lib/python3.7/site-packages/urllib3/connectionpool.py", line 382, in _make_request
    self._validate_conn(conn)
  File "/SoftDev/telefacebot-python3/lib/python3.7/site-packages/urllib3/connectionpool.py", line 1010, in _validate_conn
    conn.connect()
  File "/SoftDev/telefacebot-python3/lib/python3.7/site-packages/urllib3/connection.py", line 358, in connect
    conn = self._new_conn()
  File "/SoftDev/telefacebot-python3/lib/python3.7/site-packages/urllib3/connection.py", line 187, in _new_conn
    self, "Failed to establish a new connection: %s" % e
urllib3.exceptions.NewConnectionError: <urllib3.connection.HTTPSConnection object at 0x7fd2a66adbe0>: Failed to establish a new connection: [Errno -3] Temporary failure in name resolution

During handling of the above exception, another exception occurred:

Traceback (most recent call last):
  File "/SoftDev/telefacebot-python3/lib/python3.7/site-packages/requests/adapters.py", line 449, in send
    timeout=timeout
  File "/SoftDev/telefacebot-python3/lib/python3.7/site-packages/urllib3/connectionpool.py", line 756, in urlopen
    method, url, error=e, _pool=self, _stacktrace=sys.exc_info()[2]
  File "/SoftDev/telefacebot-python3/lib/python3.7/site-packages/urllib3/util/retry.py", line 574, in increment
    raise MaxRetryError(_pool, url, error or ResponseError(cause))
urllib3.exceptions.MaxRetryError: HTTPSConnectionPool(host='api.telegram.org', port=443): Max retries exceeded with url: /bot5013582202:AAF4KM0le6NMJRbsyHfVLnDbh6sdW9Hu9Rw/getUpdates?offset=1&timeout=6000 (Caused by NewConnectionError('<urllib3.connection.HTTPSConnection object at 0x7fd2a66adbe0>: Failed to establish a new connection: [Errno -3] Temporary failure in name resolution'))

During handling of the above exception, another exception occurred:

Traceback (most recent call last):
  File "./webbasicchatbot.py", line 66, in telegram_polling
    mybot.polling(none_stop=True, timeout=6000)
  File "/SoftDev/telefacebot-python3/lib/python3.7/site-packages/telebot/__init__.py", line 392, in polling
    self.__threaded_polling(none_stop, interval, timeout)
  File "/SoftDev/telefacebot-python3/lib/python3.7/site-packages/telebot/__init__.py", line 415, in __threaded_polling
    polling_thread.raise_exceptions()
  File "/SoftDev/telefacebot-python3/lib/python3.7/site-packages/telebot/util.py", line 79, in raise_exceptions
    six.reraise(self.exc_info[0], self.exc_info[1], self.exc_info[2])
  File "/SoftDev/telefacebot-python3/lib/python3.7/site-packages/six.py", line 719, in reraise
    raise value
  File "/SoftDev/telefacebot-python3/lib/python3.7/site-packages/telebot/util.py", line 60, in run
    task(*args, **kwargs)
  File "/SoftDev/telefacebot-python3/lib/python3.7/site-packages/telebot/__init__.py", line 279, in __retrieve_updates
    updates = self.get_updates(offset=(self.last_update_id + 1), timeout=timeout)
  File "/SoftDev/telefacebot-python3/lib/python3.7/site-packages/telebot/__init__.py", line 249, in get_updates
    json_updates = apihelper.get_updates(self.token, offset, limit, timeout, allowed_updates)
  File "/SoftDev/telefacebot-python3/lib/python3.7/site-packages/telebot/apihelper.py", line 194, in get_updates
    return _make_request(token, method_url, params=payload)
  File "/SoftDev/telefacebot-python3/lib/python3.7/site-packages/telebot/apihelper.py", line 58, in _make_request
    timeout=(connect_timeout, read_timeout), proxies=proxy)
  File "/SoftDev/telefacebot-python3/lib/python3.7/site-packages/requests/sessions.py", line 542, in request
    resp = self.send(prep, **send_kwargs)
  File "/SoftDev/telefacebot-python3/lib/python3.7/site-packages/requests/sessions.py", line 655, in send
    r = adapter.send(request, **kwargs)
  File "/SoftDev/telefacebot-python3/lib/python3.7/site-packages/requests/adapters.py", line 516, in send
    raise ConnectionError(e, request=request)
requests.exceptions.ConnectionError: HTTPSConnectionPool(host='api.telegram.org', port=443): Max retries exceeded with url: /bot5013582202:AAF4KM0le6NMJRbsyHfVLnDbh6sdW9Hu9Rw/getUpdates?offset=1&timeout=6000 (Caused by NewConnectionError('<urllib3.connection.HTTPSConnection object at 0x7fd2a66adbe0>: Failed to establish a new connection: [Errno -3] Temporary failure in name resolution'))

<<ERROR polling>>

Thu Dec  9 07:23:52 2021GAGAL STEMMING(word_tokenize)Traceback (most recent call last):
  File "/opt/lampp/htdocs/fileserver/SoftDev/telefacebot-python3/opt/webbasicchatbot.py", line 81, in bikinstemming
    myparagrafstem = word_tokenize(local_myparagraftemp)
  File "/SoftDev/telefacebot-python3/lib/python3.7/site-packages/nltk/tokenize/__init__.py", line 129, in word_tokenize
    sentences = [text] if preserve_line else sent_tokenize(text, language)
  File "/SoftDev/telefacebot-python3/lib/python3.7/site-packages/nltk/tokenize/__init__.py", line 107, in sent_tokenize
    return tokenizer.tokenize(text)
  File "/SoftDev/telefacebot-python3/lib/python3.7/site-packages/nltk/tokenize/punkt.py", line 1277, in tokenize
    return list(self.sentences_from_text(text, realign_boundaries))
  File "/SoftDev/telefacebot-python3/lib/python3.7/site-packages/nltk/tokenize/punkt.py", line 1334, in sentences_from_text
    return [text[s:e] for s, e in self.span_tokenize(text, realign_boundaries)]
  File "/SoftDev/telefacebot-python3/lib/python3.7/site-packages/nltk/tokenize/punkt.py", line 1334, in <listcomp>
    return [text[s:e] for s, e in self.span_tokenize(text, realign_boundaries)]
  File "/SoftDev/telefacebot-python3/lib/python3.7/site-packages/nltk/tokenize/punkt.py", line 1324, in span_tokenize
    for sentence in slices:
  File "/SoftDev/telefacebot-python3/lib/python3.7/site-packages/nltk/tokenize/punkt.py", line 1365, in _realign_boundaries
    for sentence1, sentence2 in _pair_iter(slices):
  File "/SoftDev/telefacebot-python3/lib/python3.7/site-packages/nltk/tokenize/punkt.py", line 319, in _pair_iter
    prev = next(iterator)
  File "/SoftDev/telefacebot-python3/lib/python3.7/site-packages/nltk/tokenize/punkt.py", line 1338, in _slices_from_text
    for match in self._lang_vars.period_context_re().finditer(text):
TypeError: expected string or bytes-like object



Thu Dec  9 07:23:52 2021GAGAL LEMITASI[lemmatize()]Traceback (most recent call last):
  File "/opt/lampp/htdocs/fileserver/SoftDev/telefacebot-python3/opt/webbasicchatbot.py", line 143, in lemmetasi
    local_myparagraftemp = [mylemmer.lemmatize(token) for token in tokentoken]
TypeError: 'NoneType' object is not iterable



Thu Dec  9 08:03:32 2021GAGAL LEMITASI[lemmatize()]Traceback (most recent call last):
  File "/SoftDev/telefacebot-python3/lib/python3.7/site-packages/urllib3/connectionpool.py", line 445, in _make_request
    six.raise_from(e, None)
  File "<string>", line 3, in raise_from
  File "/SoftDev/telefacebot-python3/lib/python3.7/site-packages/urllib3/connectionpool.py", line 440, in _make_request
    httplib_response = conn.getresponse()
  File "/usr/lib64/python3.7/http/client.py", line 1321, in getresponse
    response.begin()
  File "/usr/lib64/python3.7/http/client.py", line 296, in begin
    version, status, reason = self._read_status()
  File "/usr/lib64/python3.7/http/client.py", line 257, in _read_status
    line = str(self.fp.readline(_MAXLINE + 1), "iso-8859-1")
  File "/usr/lib64/python3.7/socket.py", line 589, in readinto
    return self._sock.recv_into(b)
  File "/usr/lib64/python3.7/ssl.py", line 1052, in recv_into
    return self.read(nbytes, buffer)
  File "/usr/lib64/python3.7/ssl.py", line 911, in read
    return self._sslobj.read(len, buffer)
TimeoutError: [Errno 110] Connection timed out

During handling of the above exception, another exception occurred:

Traceback (most recent call last):
  File "/SoftDev/telefacebot-python3/lib/python3.7/site-packages/requests/adapters.py", line 449, in send
    timeout=timeout
  File "/SoftDev/telefacebot-python3/lib/python3.7/site-packages/urllib3/connectionpool.py", line 756, in urlopen
    method, url, error=e, _pool=self, _stacktrace=sys.exc_info()[2]
  File "/SoftDev/telefacebot-python3/lib/python3.7/site-packages/urllib3/util/retry.py", line 532, in increment
    raise six.reraise(type(error), error, _stacktrace)
  File "/SoftDev/telefacebot-python3/lib/python3.7/site-packages/urllib3/packages/six.py", line 770, in reraise
    raise value
  File "/SoftDev/telefacebot-python3/lib/python3.7/site-packages/urllib3/connectionpool.py", line 706, in urlopen
    chunked=chunked,
  File "/SoftDev/telefacebot-python3/lib/python3.7/site-packages/urllib3/connectionpool.py", line 447, in _make_request
    self._raise_timeout(err=e, url=url, timeout_value=read_timeout)
  File "/SoftDev/telefacebot-python3/lib/python3.7/site-packages/urllib3/connectionpool.py", line 354, in _raise_timeout
    self, url, "Read timed out. (read timeout=%s)" % timeout_value
urllib3.exceptions.ReadTimeoutError: HTTPSConnectionPool(host='api.telegram.org', port=443): Read timed out. (read timeout=9999)

During handling of the above exception, another exception occurred:

Traceback (most recent call last):
  File "/opt/lampp/htdocs/fileserver/SoftDev/telefacebot-python3/opt/webbasicchatbot.py", line 274, in jawab_pesan
    mybot.reply_to(pesan, jawaban)
  File "/SoftDev/telefacebot-python3/lib/python3.7/site-packages/telebot/__init__.py", line 1236, in reply_to
    return self.send_message(message.chat.id, text, reply_to_message_id=message.message_id, **kwargs)
  File "/SoftDev/telefacebot-python3/lib/python3.7/site-packages/telebot/__init__.py", line 601, in send_message
    reply_markup, parse_mode, disable_notification, timeout))
  File "/SoftDev/telefacebot-python3/lib/python3.7/site-packages/telebot/apihelper.py", line 154, in send_message
    return _make_request(token, method_url, params=payload, method='post')
  File "/SoftDev/telefacebot-python3/lib/python3.7/site-packages/telebot/apihelper.py", line 58, in _make_request
    timeout=(connect_timeout, read_timeout), proxies=proxy)
  File "/SoftDev/telefacebot-python3/lib/python3.7/site-packages/requests/sessions.py", line 542, in request
    resp = self.send(prep, **send_kwargs)
  File "/SoftDev/telefacebot-python3/lib/python3.7/site-packages/requests/sessions.py", line 655, in send
    r = adapter.send(request, **kwargs)
  File "/SoftDev/telefacebot-python3/lib/python3.7/site-packages/requests/adapters.py", line 529, in send
    raise ReadTimeout(e, request=request)
requests.exceptions.ReadTimeout: HTTPSConnectionPool(host='api.telegram.org', port=443): Read timed out. (read timeout=9999)



Thu Dec  9 10:52:35 2021
<<ERROR polling>>
Traceback (most recent call last):
  File "/SoftDev/telefacebot-python3/lib/python3.7/site-packages/urllib3/connectionpool.py", line 445, in _make_request
    six.raise_from(e, None)
  File "<string>", line 3, in raise_from
  File "/SoftDev/telefacebot-python3/lib/python3.7/site-packages/urllib3/connectionpool.py", line 440, in _make_request
    httplib_response = conn.getresponse()
  File "/usr/lib64/python3.7/http/client.py", line 1321, in getresponse
    response.begin()
  File "/usr/lib64/python3.7/http/client.py", line 296, in begin
    version, status, reason = self._read_status()
  File "/usr/lib64/python3.7/http/client.py", line 257, in _read_status
    line = str(self.fp.readline(_MAXLINE + 1), "iso-8859-1")
  File "/usr/lib64/python3.7/socket.py", line 589, in readinto
    return self._sock.recv_into(b)
  File "/usr/lib64/python3.7/ssl.py", line 1052, in recv_into
    return self.read(nbytes, buffer)
  File "/usr/lib64/python3.7/ssl.py", line 911, in read
    return self._sslobj.read(len, buffer)
socket.timeout: The read operation timed out

During handling of the above exception, another exception occurred:

Traceback (most recent call last):
  File "/SoftDev/telefacebot-python3/lib/python3.7/site-packages/requests/adapters.py", line 449, in send
    timeout=timeout
  File "/SoftDev/telefacebot-python3/lib/python3.7/site-packages/urllib3/connectionpool.py", line 756, in urlopen
    method, url, error=e, _pool=self, _stacktrace=sys.exc_info()[2]
  File "/SoftDev/telefacebot-python3/lib/python3.7/site-packages/urllib3/util/retry.py", line 532, in increment
    raise six.reraise(type(error), error, _stacktrace)
  File "/SoftDev/telefacebot-python3/lib/python3.7/site-packages/urllib3/packages/six.py", line 770, in reraise
    raise value
  File "/SoftDev/telefacebot-python3/lib/python3.7/site-packages/urllib3/connectionpool.py", line 706, in urlopen
    chunked=chunked,
  File "/SoftDev/telefacebot-python3/lib/python3.7/site-packages/urllib3/connectionpool.py", line 447, in _make_request
    self._raise_timeout(err=e, url=url, timeout_value=read_timeout)
  File "/SoftDev/telefacebot-python3/lib/python3.7/site-packages/urllib3/connectionpool.py", line 337, in _raise_timeout
    self, url, "Read timed out. (read timeout=%s)" % timeout_value
urllib3.exceptions.ReadTimeoutError: HTTPSConnectionPool(host='api.telegram.org', port=443): Read timed out. (read timeout=6010)

During handling of the above exception, another exception occurred:

Traceback (most recent call last):
  File "/opt/lampp/htdocs/fileserver/SoftDev/telefacebot-python3/opt/webbasicchatbot.py", line 66, in telegram_polling
    mybot.polling(none_stop=True, timeout=6000)
  File "/SoftDev/telefacebot-python3/lib/python3.7/site-packages/telebot/__init__.py", line 392, in polling
    self.__threaded_polling(none_stop, interval, timeout)
  File "/SoftDev/telefacebot-python3/lib/python3.7/site-packages/telebot/__init__.py", line 415, in __threaded_polling
    polling_thread.raise_exceptions()
  File "/SoftDev/telefacebot-python3/lib/python3.7/site-packages/telebot/util.py", line 79, in raise_exceptions
    six.reraise(self.exc_info[0], self.exc_info[1], self.exc_info[2])
  File "/SoftDev/telefacebot-python3/lib/python3.7/site-packages/six.py", line 719, in reraise
    raise value
  File "/SoftDev/telefacebot-python3/lib/python3.7/site-packages/telebot/util.py", line 60, in run
    task(*args, **kwargs)
  File "/SoftDev/telefacebot-python3/lib/python3.7/site-packages/telebot/__init__.py", line 279, in __retrieve_updates
    updates = self.get_updates(offset=(self.last_update_id + 1), timeout=timeout)
  File "/SoftDev/telefacebot-python3/lib/python3.7/site-packages/telebot/__init__.py", line 249, in get_updates
    json_updates = apihelper.get_updates(self.token, offset, limit, timeout, allowed_updates)
  File "/SoftDev/telefacebot-python3/lib/python3.7/site-packages/telebot/apihelper.py", line 194, in get_updates
    return _make_request(token, method_url, params=payload)
  File "/SoftDev/telefacebot-python3/lib/python3.7/site-packages/telebot/apihelper.py", line 58, in _make_request
    timeout=(connect_timeout, read_timeout), proxies=proxy)
  File "/SoftDev/telefacebot-python3/lib/python3.7/site-packages/requests/sessions.py", line 542, in request
    resp = self.send(prep, **send_kwargs)
  File "/SoftDev/telefacebot-python3/lib/python3.7/site-packages/requests/sessions.py", line 655, in send
    r = adapter.send(request, **kwargs)
  File "/SoftDev/telefacebot-python3/lib/python3.7/site-packages/requests/adapters.py", line 529, in send
    raise ReadTimeout(e, request=request)
requests.exceptions.ReadTimeout: HTTPSConnectionPool(host='api.telegram.org', port=443): Read timed out. (read timeout=6010)

<<ERROR polling>>

Fri Dec 10 05:21:05 2021GAGAL STEMMING(word_tokenize)Traceback (most recent call last):
  File "./webbasicchatbot.py", line 81, in bikinstemming
    myparagrafstem = word_tokenize(local_myparagraftemp)
  File "/SoftDev/telefacebot-python3/lib/python3.7/site-packages/nltk/tokenize/__init__.py", line 129, in word_tokenize
    sentences = [text] if preserve_line else sent_tokenize(text, language)
  File "/SoftDev/telefacebot-python3/lib/python3.7/site-packages/nltk/tokenize/__init__.py", line 107, in sent_tokenize
    return tokenizer.tokenize(text)
  File "/SoftDev/telefacebot-python3/lib/python3.7/site-packages/nltk/tokenize/punkt.py", line 1277, in tokenize
    return list(self.sentences_from_text(text, realign_boundaries))
  File "/SoftDev/telefacebot-python3/lib/python3.7/site-packages/nltk/tokenize/punkt.py", line 1334, in sentences_from_text
    return [text[s:e] for s, e in self.span_tokenize(text, realign_boundaries)]
  File "/SoftDev/telefacebot-python3/lib/python3.7/site-packages/nltk/tokenize/punkt.py", line 1334, in <listcomp>
    return [text[s:e] for s, e in self.span_tokenize(text, realign_boundaries)]
  File "/SoftDev/telefacebot-python3/lib/python3.7/site-packages/nltk/tokenize/punkt.py", line 1324, in span_tokenize
    for sentence in slices:
  File "/SoftDev/telefacebot-python3/lib/python3.7/site-packages/nltk/tokenize/punkt.py", line 1365, in _realign_boundaries
    for sentence1, sentence2 in _pair_iter(slices):
  File "/SoftDev/telefacebot-python3/lib/python3.7/site-packages/nltk/tokenize/punkt.py", line 319, in _pair_iter
    prev = next(iterator)
  File "/SoftDev/telefacebot-python3/lib/python3.7/site-packages/nltk/tokenize/punkt.py", line 1338, in _slices_from_text
    for match in self._lang_vars.period_context_re().finditer(text):
TypeError: expected string or bytes-like object



Fri Dec 10 05:21:05 2021GAGAL LEMITASI[lemmatize()]Traceback (most recent call last):
  File "./webbasicchatbot.py", line 143, in lemmetasi
    local_myparagraftemp = [mylemmer.lemmatize(token) for token in tokentoken]
TypeError: 'NoneType' object is not iterable

